Workbook

Sheet Guidance

Sheet Implementation Plan
A1: Implementation Plan | F1: Activity | J1: Deliverable | O1: Milestone
A2: Legend: Activity = blue (col D) | D = Deliverable completed (green) | M = Milestone (amber). The implementation period is 36 months; all completion markers fall within Years 1-3 and Year 4 is not applicable.
A3: Please list all key activities under relevant Readiness Objective, Outcome and Output, in line with the Logical Framework (Logframe). Indicate the timeline of activities, including when each milestone or deliverable is expected to be achieved or completed
A4: Please add rows as necessary and delete rows that are not relevant to the proposal.
A5: Objectives | B5: Outcomes | C5: Outputs | D5: Activities list all key activities that contribute to the achievement of the deliverables | E5: Year 1 | I5: Year 2 | M5: Year 3 | Q5: Not applicable — programme ends at Month 36
E6: Q1 | F6: Q2 | G6: Q3 | H6: Q4 | I6: Q1 | J6: Q2 | K6: Q3 | L6: Q4 | M6: Q1 | N6: Q2 | O6: Q3 | P6: Q4 | Q6: N/A | R6: N/A | S6: N/A | T6: N/A
A7: Objective 1 Capacity-building for climate finance coordination and setting up the enabling environment for integrated climate investment | B7: Outcome 1.1 Developing countries, through NDAs or focal points, have enhanced capacity to fulfil their roles, responsibilities and policy requirements, including coordination mechanisms to engage relevant stakeholders to develop, advance, and implement NDCs, NAPs and LTS | C7: Output 1.1.1 NDA/focal point and other climate stakeholders have enhanced their capacity to fulfil their roles and responsibilities to develop, advance and implement NDCs, NAPs and LTSs | D7: 1-1-1.a. Develop and operationalize the NDA four-year strategic and operational
D8: 1-1-1.b. Establish a functional operational system for the NDA Secretariat
D9: 1-1-1.c. Conduct an institutional assessment of climate coordination capacities
D10: 1-1-1.d. Roll out a modular capacity-building programme | G10: M | H10: D
C11: Output 1.1.2 An inclusive Coordination Mechanism has enhanced capacity to fulfill its mandate to develop, advance and implement NDCs, NAPs and LTSs | D11: 1-1-2.a. Establish and institutionalize the National Climate Finance Coordination Platform
D12: 1-1-2.b. Formalize the participation of the Ministry of Economy and Finance
D13: 1-1-2.c. Formalize the participation of the Central Bank
D14: 1-1-2.d. Establish a standardized coordination, screening, prioritization and no-objection process
D15: 1-1-2.e. Organize periodic dialogues with financial actors and climate partners | H15: M | J15: D
B16: Outcome 1.2 Developing countries design and implement strategic frameworks (including NDC/NAP/LTS), policies and instruments, including climate investment plans, to create enabling environments for integrated climate investments | C16: Output 1.2.1 Inclusive strategic frameworks (NDCs, NAPs, and LTSs) and policy instruments are created, updated and/or strengthened | D16: 1-2- 1.a. Develop a national climate finance roadmap
D17: 1-2-1.b. Establish an executive mechanism for tracking climate finance
D18: 1-2-1.c. Develop a preliminary green taxonomy
D19: 1-2-1.d. Design risk-reduction mechanisms
D20: 1-2-1.e. Develop sectoral climate investment roadmaps | I20: M | K20: D
B21: Outcome 1.3 Direct access applicants and accredited entities (DAEs) have met and maintained the accreditation standards of the GCF and strengthened their programming capacities, as evidenced by the development of GCF-funded activities | C21: Output 1.3.1 Institutional gaps of direct access applicants and accredited entities (DAEs) are addressed to obtain and/or maintain accreditation | D21: 1-3-1.a. Individualized gap assessments for ANAFIC and Access Bank
D22: 1-3-1.b. Review and adopt internal policies required for GCF compliance, supported by an embedded accreditation technical advisor
D23: 1-3-1.c. Translate future GCF Panel conditions into post-accreditation action plans
D24: 1-3-1.d. Establish internal GCF units in each candidate entity.
D25: 1-3-1.e. Organize project clinics and targeted coaching for candidate entities
D26: 1-3-1.f. Conduct system stress-testing and strengthen reporting connected to the NDA | J26: M | L26: D
A27: Objective 2 Paradigm-shifting GCF pipeline development and implementation for adaptation and mitigation, based on country needs and guided by USP-2 programming targets | B27: Outcome 2.1 Developing countries have developed or updated their country programmes to guide GCF investment | C27: Output 2.1.1 An inclusive Country Programme has articulated the country’s needs and climate priorities1 | D27: 2-1-1.a. Not budgeted as a standalone activity
D28: 2-1-1.b. Not budgeted as a standalone activity.
D29: 2-1-1.c. Not budgeted as a standalone activity | E29: D8 removed (no budget)
B30: Outcome 2.2 Developing countries have developed high-quality Concept Notes linked to approved GCF proposals for adaptation and mitigation that are aligned with the USP-2 results (including through DAEs, that build on readiness support and Country Programmes) | C30: Output 2.2.1 NDA, DAEs and other climate stakeholders, have enhanced their capacity on Concept Note and/or Funding Proposal development for an inclusive integrated climate programming1 | D30: 2-2-1.a. Roll out a practical climate project preparation programme
D31: 2-2-1.b. Organize pipeline maturation clinics
D32: 2-2-1.c. Conduct the necessary pre-feasibility studies and technical analyses | K32: M | M32: D
C33: Output 2.2.2 Investment-grade Concept Notes and submission-ready Funding Proposals aligned with national priorities; GCF screening status reported separately | D33: 2-2-2.a. Develop five firm-developed investment-grade Concept Notes (CNs)
D34: 2-2-2.b. Prepare three Funding Proposals (FPs) and submit them for GCF screening, subject to NDA validation
D35: 2-2-2.c. Establish a quality screening process before submission | M35: M | O35: D
B36: Outcome 2.3 NDAs and DAEs have enhanced processes and systems to effectively oversee the implementation, financial management, monitoring and reporting of climate programmes and projects | C36: Output 2.3.1 NDA and DAEs have enhanced relevant capacity, processes and systems in place to design, oversee and implement climate programmes and projects | D36: 2-3-1.a. Establish a national ESS, gender and fiduciary compliance gateway
D37: 2-3-1.b. Develop a national climate finance portfolio dashboard
D38: 2-3-1.c. Strengthen the reporting systems of ANAFIC and Access Bank Guinea
D39: 2-3-1.d. Establish a national continuous capacity-building programme for candidate direct access entities and accredited entities, where applicable | L39: M | P39: D
A40: Objective 3 Knowledge-sharing and learning to enhance national and regional cooperation on climate programming and financing | B40: Outcome 3.1 Developing countries, through NDAs or focal points, have made use of knowledge products to address policy gaps and integrated climate investment programming and implementation | C40: Output 3.1.1 Climate knowledge products and resources are generated and disseminated to develop or advance policies, programming and/or implementation | D40: 3-1-1.a. Roll out a national climate knowledge management portal
...

Sheet Budget Plan
A1: Budget Plan
A3: Please specify the Budget Categories for each Deliverable that will trigger payments. Please add rows as required and skip rows that are not relevant. Additional budget categories may be added by manually typing them on the Budget Category sheet.
A5: Objectives | B5: Outcomes | C5: Deliverables choose from the drop-down list | D5: Milestones list all relevant milestones press Alt + Enter to add a new line | E5: Detailed Budget (in US$) | L5: Total Budget per objective | M5: Total budget % per objective | N5: Executing Entity | O5: Budget notes
E6: Budget Categories choose from the drop-down list | F6: Unit | G6: # of Unit | H6: Unit Cost | I6: Total Budget per budget category | J6: Total Budget per deliverable | K6: Total Budget per outcome
A8: Objective 1 Capacity-building for climate finance coordination and setting up the enabling environment for integrated climate investment Target budget: 30% | B8: Outcome 1.1 Developing countries, through NDAs or focal points, have enhanced capacity to fulfil their roles, responsibilities and policy requirements, including coordination mechanisms to engage relevant stakeholders2 to develop, advance, and implement NDCs, NAPs and LTS | C8: D1. Status report on capacity building of NDA and climate stakeholders | D8: M1.1 NDA four-year strategic & operational plan adopted M1.2 NDA Secretariat operational system established M1.3 Institutional capacity assessment of climate coordination completed M1.4 Modular capacity-building programme delivered | E8: Consultant - Individual - International | F8: Day | G8: 20 | H8: 500 | I8: =G8*H8 -> 10000 | J8: =SUM(I8:I11) -> 150000 | K8: =SUM(J8:J15) -> 270000 | L8: =SUM(K8:K35) -> 660000 | M8: =((($O$77+$O$78+$O$79+$O$83)*(L8/$L$64))+L8)/$O$86 -> 0.3 | O8: A
E9: Consultant - Individual - Local | F9: Day | G9: 150 | H9: 350 | I9: =G9*H9 -> 52500 | O9: B
E10: Professional Services – Companies/Firm | F10: Lumpsum | G10: 1 | H10: 60500 | I10: =G10*H10 -> 60500 | O10: C
E11: Workshop/Training | F11: Event | G11: 6 | H11: 4500 | I11: =G11*H11 -> 27000 | O11: D
C12: D2. Status report on country coordination mechanism, country (or regional) platform for enhanced climate finance access to develop, advance, and implement NDCs, NAPs and LTS | D12: M2.1 National Climate Finance Coordination Platform established & institutionalized M2.2 MEF participation formalized M2.3 Central Bank participation formalized M2.4 Standardized screening/no-objection process & periodic dialogues | E12: Consultant - Individual - Local | F12: Day | G12: 100 | H12: 350 | I12: =G12*H12 -> 35000 | J12: =SUM(I12:I15) -> 120000
E13: Professional Services – Companies/Firm | F13: Lumpsum | G13: 1 | H13: 45000 | I13: =G13*H13 -> 45000
E14: Workshop/Training | F14: Event | G14: 6 | H14: 5000 | I14: =G14*H14 -> 30000
E15: Communication | F15: Lumpsum | G15: 1 | H15: 10000 | I15: =G15*H15 -> 10000
B16: Outcome 1.2 Developing countries design and implement strategic frameworks (including NDC/NAP/LTS), policies and instruments, including climate investment plans, to create enabling environments for integrated climate investments | C16: D3. Status report on the national adaptation plan (NAP) | D16: M3.1 NAP diagnostic & documentation completed M3.2 NAP validation workshop & status report | E16: Consultant - Individual - Local | F16: Day | G16: 50 | H16: 350 | I16: =G16*H16 -> 17500 | J16: =SUM(I16:I19) -> 30000 | K16: =SUM(J16:J31) -> 190000
E17: Professional Services – Companies/Firm | F17: Lumpsum | G17: 1 | H17: 8000 | I17: =G17*H17 -> 8000
E18: Workshop/Training | F18: Event | G18: 1 | H18: 3000 | I18: =G18*H18 -> 3000
E19: Audio Visual & Printing | F19: Lumpsum | G19: 1 | H19: 1500 | I19: =G19*H19 -> 1500
C20: D4. Status report on the nationally determined contribution (NDC) | D20: M4.1 NDC analysis & international expert input completed M4.2 NDC multi-stakeholder validation & status report | E20: Consultant - Individual - International | F20: Day | G20: 15 | H20: 500 | I20: =G20*H20 -> 7500 | J20: =SUM(I20:I23) -> 45000
E21: Consultant - Individual - Local | F21: Day | G21: 60 | H21: 350 | I21: =G21*H21 -> 21000
E22: Professional Services – Companies/Firm | F22: Lumpsum | G22: 1 | H22: 11500 | I22: =G22*H22 -> 11500
E23: Workshop/Training | F23: Event | G23: 1 | H23: 5000 | I23: =G23*H23 -> 5000
C24: D5. Status report on the long term climate strategies (LTS) | D24: M5.1 LTS documentation & consultancy completed M5.2 LTS validation workshop & status report | E24: Consultant - Individual - Local | F24: Day | G24: 40 | H24: 350 | I24: =G24*H24 -> 14000 | J24: =SUM(I24:I27) -> 25000
E25: Professional Services – Companies/Firm | F25: Lumpsum | G25: 1 | H25: 7000 | I25: =G25*H25 -> 7000
E26: Workshop/Training | F26: Event | G26: 1 | H26: 2500 | I26: =G26*H26 -> 2500
E27: Audio Visual & Printing | F27: Lumpsum | G27: 1 | H27: 1500 | I27: =G27*H27 -> 1500
C28: D6. Status report on policies, regulations and mechanisms developed or enhanced to incentivize private sector engagement | D28: M6.1 Sectoral climate investment roadmaps & policy analysis M6.2 Risk-reduction / green-taxonomy instruments developed M6.3 Sectoral validation workshops & status report | E28: Consultant - Individual - International | F28: Day | G28: 40 | H28: 500 | I28: =G28*H28 -> 20000 | J28: =SUM(I28:I31) -> 90000
E29: Consultant - Individual - Local | F29: Day | G29: 80 | H29: 350 | I29: =G29*H29 -> 28000
E30: Workshop/Training | F30: Event | G30: 3 | H30: 10000 | I30: =G30*H30 -> 30000
E31: Audio Visual & Printing | F31: Lumpsum | G31: 1 | H31: 12000 | I31: =G31*H31 -> 12000
B32: Outcome 1.3 Direct access applicants and accredited entities (DAEs) have met and maintained the accreditation standards of the GCF and strengthened their programming capacities, as evidenced by the development of GCF-funded activities | C32: D7. Status report on capacity building of direct access applicants and accredited entities to meet GCF accreditation requirements | D32: M7.1 Gap assessments for ANAFIC & Access Bank Guinea completed M7.2 Internal GCF units, policies & post-accreditation action plans adopted M7.3 Project clinics, system stress-testing & status report | E32: Consultant - Individual - International | F32: Day | G32: 80 | H32: 500 | I32: =G32*H32 -> 40000 | J32: =SUM(I32:I35) -> 200000 | K32: =SUM(J32) -> 200000
E33: Consultant - Individual - Local | F33: Day | G33: 120 | H33: 350 | I33: =G33*H33 -> 42000
E34: Professional Services – Companies/Firm | F34: Lumpsum | G34: 1 | H34: 100000 | I34: =G34*H34 -> 100000
E35: Workshop/Training | F35: Event | G35: 4 | H35: 4500 | I35: =G35*H35 -> 18000
A36: Objective 2 Paradigm shifting GCF pipeline development and implementation for adaptation and mitigation, based on country needs and guided by USP-2 programming targets Target budget: 60% | B36: Outcome 2.1 Developing countries have developed or updated their country programmes to guide GCF investment. | C36: D8. Country Programme Document | J36: =SUM(I36:I39) -> 0 | K36: =SUM(J36) -> 0 | L36: =SUM(J36:J51) -> 1320000 | M36: =((($O$77+$O$78+$O$79+$O$83)*(L36/$L$64))+L36)/$O$86 -> 0.6 | O36: G
B40: Outcome 2.2 Developing countries have developed high-quality concept notes linked to approved GCF proposals for adaptation and mitigation that are aligned with the USP-2 results, including through DAEs, that build on readiness support and country programmes | C40: D9. Concept Note(s), and studies, assessment, reports, etc. to support the development of investment-grade Concept Notes | D40: M9.1 Pipeline maturation clinics & pre-feasibility studies M9.2 Five firm-developed investment-grade Concept Notes prepared M9.3 CN quality-screening & NDA validation | E40: Professional Services – Companies/Firm | F40: Lumpsum | G40: 5 | H40: 30000 | I40: =+G40*H40 -> 150000 | J40: =SUM(I40:I43) -> 228000 | K40: =SUM(J40:J47) -> 928000
E41: Consultant - Individual - International | F41: Day | G41: 40 | H41: 500 | I41: =+G41*H41 -> 20000
E42: Consultant - Individual - Local | F42: Day | G42: 80 | H42: 350 | I42: =+G42*H42 -> 28000
E43: Office Supplies | F43: Lumpsum | G43: 3 | H43: 10000 | I43: =+G43*H43 -> 30000
C44: D10. Funding Proposal(s), and studies, assessment, reports, etc. to support the development of investment-grade Funding Proposals | D44: M10.1 Feasibility, ESIA/ESS & gender assessments M10.2 Three fully-developed Funding Proposals prepared M10.3 FP screening & submission for GCF review | E44: Professional Services – Companies/Firm | F44: Funding Proposal | G44: 3 | H44: 170000 | I44: =+G44*H44 -> 510000 | J44: =SUM(I44:I47) -> 700000
E45: Consultant - Individual - International | F45: Day | G45: 240 | H45: 500 | I45: =+G45*H45 -> 120000
E46: Consultant - Individual - Local | F46: Day | G46: 170 | H46: 350 | I46: =+G46*H46 -> 59500
...

Sheet Disbursement Schedule
A1: Disbursement Schedule
A3: Please provide an indicative disbursement schedule based on the percentage of each milestone budget against total budget for each deliverable. Ensure alignment with expected timelines in the implementation plan. Please add or delete rows as necessary.
A5: Deliverables and Milestones | B5: Budget | C5: % | E5: Y1 | F5: Y2 | G5: Y3 | H5: N/A (36M) | I5: Cumulative
A6: D1. Status report on capacity building of NDA and climate stakeholders | B6: 150000 | C6: 0.068181818
A7: M1.1 NDA four-year strategic & operational plan adopted | C7: 0.3 | E7: 45000 | I7: =SUM(E7:H7) -> 45000
A8: M1.2 NDA Secretariat operational system established | C8: 0.25 | E8: 37500 | I8: =SUM(E8:H8) -> 37500
A9: M1.3 Institutional capacity assessment completed | C9: 0.2 | E9: 30000 | I9: =SUM(E9:H9) -> 30000
A10: M1.4 Modular capacity-building programme delivered | C10: 0.25 | F10: 37500 | I10: =SUM(E10:H10) -> 37500
A11: D2. Status report on country coordination mechanism / country platform | B11: 120000 | C11: 0.054545455
A12: M2.1 National Climate Finance Coordination Platform established | C12: 0.4 | E12: 48000 | I12: =SUM(E12:H12) -> 48000
A13: M2.2 MEF participation formalized | C13: 0.2 | E13: 24000 | I13: =SUM(E13:H13) -> 24000
A14: M2.3 Central Bank participation formalized | C14: 0.2 | F14: 24000 | I14: =SUM(E14:H14) -> 24000
A15: M2.4 Standardized screening/no-objection process & dialogues | C15: 0.2 | F15: 24000 | I15: =SUM(E15:H15) -> 24000
A16: D3. Status report on the national adaptation plan (NAP) | B16: 30000 | C16: 0.013636364
A17: M3.1 NAP diagnostic & documentation completed | C17: 0.6 | E17: 18000 | I17: =SUM(E17:H17) -> 18000
A18: M3.2 NAP validation workshop & status report | C18: 0.4 | E18: 12000 | I18: =SUM(E18:H18) -> 12000
I19: =SUM(E19:H19) -> 0
I20: =SUM(E20:H20) -> 0
A21: D4. Status report on the nationally determined contribution (NDC) | B21: 45000 | C21: 0.020454545
A22: M4.1 NDC analysis & international expert input completed | C22: 0.6 | E22: 27000 | I22: =SUM(E22:H22) -> 27000
A23: M4.2 NDC multi-stakeholder validation & status report | C23: 0.4 | F23: 18000 | I23: =SUM(E23:H23) -> 18000
I24: =SUM(E24:H24) -> 0
I25: =SUM(E25:H25) -> 0
A26: D5. Status report on the long term climate strategies (LTS) | B26: 25000 | C26: 0.011363636
A27: M5.1 LTS documentation & consultancy completed | C27: 0.7 | F27: 17500 | I27: =SUM(E27:H27) -> 17500
A28: M5.2 LTS validation workshop & status report | C28: 0.3 | F28: 7500 | I28: =SUM(E28:H28) -> 7500
I29: =SUM(E29:H29) -> 0
I30: =SUM(E30:H30) -> 0
A31: D6. Status report on policies/regulations to incentivize private sector engagement | B31: 90000 | C31: 0.040909091
A32: M6.1 Sectoral climate investment roadmaps & policy analysis | C32: 0.55 | E32: 49500 | I32: =SUM(E32:H32) -> 49500
A33: M6.2 Risk-reduction / green-taxonomy instruments developed | C33: 0.25 | F33: 22500 | I33: =SUM(E33:H33) -> 22500
A34: M6.3 Sectoral validation workshops & status report | C34: 0.2 | F34: 18000 | I34: =SUM(E34:H34) -> 18000
I35: =SUM(E35:H35) -> 0
A36: D7. Status report on capacity building of direct access applicants and accredited entities | B36: 200000 | C36: 0.090909091
A37: M7.1 Gap assessments for ANAFIC & Access Bank completed | C37: 0.4 | E37: 80000 | I37: =SUM(E37:H37) -> 80000
A38: M7.2 Internal GCF units, policies & action plans adopted | C38: 0.35 | F38: 70000 | I38: =SUM(E38:H38) -> 70000
A39: M7.3 Project clinics, stress-testing & status report | C39: 0.25 | G39: 50000 | I39: =SUM(E39:H39) -> 50000
I40: =SUM(E40:H40) -> 0
A41: D9. Concept Note(s) and supporting studies for investment-grade Concept Notes | B41: 228000 | C41: 0.10363636
A42: M9.1 Pipeline maturation clinics & pre-feasibility studies | C42: 0.25 | E42: 57000 | I42: =SUM(E42:H42) -> 57000
...

Sheet Fee request
A1: Fee request budget
B3: Y1 | C3: Y2 | D3: Y3 | E3: N/A (36M) | F3: N/A | G3: N
A4: Currency: | B4: USD/EUR/Other (Please Specify including Forex rate used)
A5: Project/Program Implementation and Supervision
A6: Implementation Start-Up
A7: Appraising and finalizing project implementation arrangements, including mission travel | B7: 4410
A8: Assisting and advising the project proponent on the establishment of project management structure in the recipient country | B8: 4410
A9: Assisting project management to draft TORs and advising on the selection of experts for implementation | B9: 5145
A10: Advising on and participating in project start-up workshop. | B10: 4410
A11: Technical Supervision
A12: Conducting supervision missions, including briefing operational focal points on project progress | B12: 2205 | C12: 546 | D12: 2205
A13: Providing technical guidance, as necessary, for project implementation | B13: 2205 | C13: 5145 | D13: 2205
A14: As necessary, technical consultants during supervision missions to advise government officials on technical matters and provide technical assistance for the project | B14: 1470 | C14: 1240 | D14: 1470
A15: Overseeing procurement and financial management to ensure implementation is in line with AE’s policies and timeline | B15: 1470 | C15: 3675 | D15: 1470
A16: Undertaking the mid-term review, including possible project restructuring | B16: 1237 | C16: 1470 | D16: 1236
A17: Administrative Oversight
A18: Disbursing funds to the Executing entities/vendors and reviewing financial reports | B18: 2205 | C18: 2205 | D18: 2205
A19: Assisting and overseeing the audit process throughout the project life cycle | B19: 1470 | C19: 1470 | D19: 1470
A20: Overseeing the preparation of the required reports for submission to the GCF Secretariat | B20: 1470 | C20: 1470 | D20: 1470
A21: Monitoring and reviewing project expenditure reports | B21: 735 | C21: 735 | D21: 735
A22: Preparing periodic revisions to reflect changes in annual expense category budgets | B22: 0 | C22: 735
A23: Other (please specify):
B24: 3675 | D24: 3675
A27: Project/Program Completion and Evaluation
A28: Program closure
A29: Preparing project closing documents for submission to GCF Secretariat | D29: 7349
A30: Preparing the financial closure of the project for submission to GCF Secretariat | D30: 36743
A31: Reporting and Evaluation
A32: Overseeing the preparation of the Project Completion Report/Independent Terminal Evaluation, submitting the report to the GCF Secretariat | D32: 7349
A33: Other (please specify):
A36: Reporting, as required under Agreement
A37: Reporting requirements as agreed in the agreement
A38: Other (please specify):
A42: Total | G42: =SUM(B7:G41) -> 124790
A43: Fee Percentage | G43: =G42/'Budget Plan'!O81 -> 0.05
A44: All fee activities and payments are phased within Years 1-3 of the confirmed 36-month implementation period.
A45: * Budget lines are indicative of the level of detail requested. Categories may be added/removed as relevant to each project.

Sheet Budget Category
A1: Budget Categories
A4: Audio Visual & Printing
A5: Audit Fee
A6: Communication
A7: Consultant - Individual - International
A8: Consultant - Individual - Local
A9: Professional Services – Companies/Firm
A10: Office Supplies
A11: Travel - International
A12: Travel – Local
A13: Workshop/Training
A21: Choose percentage
A22: 0
A23: 0.01
A24: 0.02
A25: 0.03

Sheet Budget Notes
A1: Budget Notes
A3: Please check out the example in the table below, and remove them before including the proposal's entries
A5: Budget Note | B5: Detailed Description
A6: A | B6: International Consultants — senior GCF accreditation / DAE expert (D7): budgeted at the confirmed USD 500/day benchmark, 80 days = USD 40,000. Supports institutional diagnostics for NDA-validated candidate entities (ANAFIC and Access Bank Guinea, subject to GCF Accreditation Team confirmation), preparation of documentation aligned with GCF governance, ESMS, gender and financial-management standards, and responses to Secretariat observations. Additional international inputs at USD 500/day are budgeted under D4 (NDC), D6 (private-sector policy), D9 (Concept Notes) and D10 (Funding Proposals).
A7: B | B7: Local Consultants — the local consultant rate is standardised at USD 350/day across every deliverable (previously USD 350–400/day), consistent with the Guinean market. Illustrative local inputs: D7 accreditation support 120 days x USD 350 = USD 42,000; D1 capacity-building 150 days; D9 Concept Notes 80 days; D10 Funding Proposals 170 days; D11 systems and oversight 200 days. Local consultants cover data collection, deliverable preparation, validation workshops and support to concept notes and funding proposals. The National Project Management Coordinator (PMC) provides operational supervision over 36 months at USD 4,000/month = USD 144,000; with external audit (USD 15,000) and financial-management/reporting support (USD 9,000), total PMC is USD 168,000, i.e. 7.43% of the deliverables-plus-evaluation base — within the 7.5% Readiness threshold. Deliverable budgets have been rebalanced to the 30% / 60% / 10% split across Objectives 1, 2 and 3.
A8: C | B8: Professional Services (firms) — awarded through competitive procurement consistent with GCF and national procedures. Final firm packages: D7 accreditation-support firm USD 100,000 (embedded advisory, fiduciary and institutional gap assessment covering governance, ESMS, gender, audit and financial management); D2 coordination support USD 45,000; D9 five firm-developed concept-note packages USD 150,000; D10 three fully-developed Funding Proposals USD 510,000; D11 systems build (national ESS/gender/fiduciary gateway, portfolio dashboard, entity reporting systems) USD 268,000; D12 knowledge products USD 65,000; plus smaller firm inputs under D1, D3, D4, D5 and D14. See Notes H and L for the D9 and D10 composition.
A9: D | B9: Workshops and Events — delivered across the three programme years. D1 (NDA/stakeholder capacity): 6 workshops x USD 4,500 = USD 27,000. D7 (accreditation): 4 institutional workshops x USD 4,500 = USD 18,000 — (i) GCF-requirements launch and awareness, (ii) gap-assessment validation, (iii) ESMS and gender training for candidate entities, (iv) pre-submission review and GCF interview simulation. D2 (Coordination Platform): 6 workshops x USD 5,000 = USD 30,000. D6 (private-sector policy): 3 sectoral validation workshops x USD 10,000 = USD 30,000. D12: 2 knowledge events x USD 10,000. D13: 3 knowledge-sharing events x USD 10,000. D14: 1 regional event x USD 15,000. Single validation workshops are also budgeted under D3, D4 and D5. Each workshop covers venue, learning materials, facilitation fees and participant travel.
A10: E | B10: Deliverables D3/D4/D5 — status reports on Guinea's national climate-planning instruments. D3 (NAP): USD 30,000 — local consultancy, documentation and validation workshop. D4 (NDC): USD 45,000 — international expert input at USD 500/day, local consultancy, analysis and multi-stakeholder workshop. D5 (LTS): USD 25,000 — local consultancy, documentation and workshop. Concentrated in years 1 and 2, these deliverables align the programme with national planning instruments and GCF programming priorities.
A11: F | B11: International consultant rate — USD 500/day. All international consultant lines are set at USD 500/day, in full alignment with GCF comment #5 and the international rate approved for Guinea in 2025.
A12: G | B12: D8 Country Programme — removed. Per GCF comment on Outcome 2.1.1, the standalone Country Programme update is no longer recommended. Its function is absorbed into Output 1.1.2 (National Climate Finance Coordination Platform) and Output 1.2.1 (Climate Finance Roadmap). No budget is allocated to D8; the row is retained blank so that the Objective 2 total (column L) formula remains intact.
A13: H | B13: D9 Concept Notes — USD 228,000 (5 firm-developed, investment-grade CNs). Composition: five firm-developed CN packages USD 150,000; international structuring 40 days x USD 500 = USD 20,000; local expertise 80 days x USD 350 = USD 28,000; office/logistics USD 30,000. Approx. USD 45,600 per CN — within the ~USD 50,000 firm-CN benchmark.
A14: I | B14: PMC — USD 168,000 (7.43% of the deliverables-plus-evaluation base of USD 2,260,000, i.e. within the 7.5% indicative Readiness threshold). Itemisation: external audit USD 15,000 (3 annual audits); National Project Management Coordinator USD 144,000 (36 months x USD 4,000); financial management and reporting USD 9,000. PMC is 100% GCF-financed, consistent with the 100% GCF grant share.
A15: J | B15: Support-cost logic (GCF template). Contingency = 3% of (deliverables + evaluation) = 3% x USD 2,260,000 = USD 67,800. Sub-total (deliverables + evaluation + PMC + contingency) = USD 2,495,800. Fee = 5% of the sub-total = USD 124,790. TOTAL REQUEST = USD 2,620,590. The deliverable budget is rebalanced to 30% / 60% / 10% across Objectives 1–3. The revised total reduces the overage above the indicative USD 2,500,000 Readiness ceiling to USD 120,590 (from USD 268,488); the NDA has validated submission of the package. If the Secretariat determines that any D10 full Funding Proposal preparation should be treated under the Project Preparation Facility, the NDA will work with GCF to adjust the financing route without affecting the integrity of the remaining Readiness package.
A16: K | B16: Independent Evaluation — USD 60,000, aligned with typical independent final-evaluation costs for a 36-month Readiness grant. (This corrects a residual USD 10,000 value carried in the working file; USD 60,000 is the reconciled figure.)
... A18: M | B18: Objective rebalancing — the deliverable budget is set to Objective 1 = 30% (USD 660,000), Objective 2 = 60% (USD 1,320,000) and Objective 3 = 10% (USD 220,000), total USD 2,200,000. Shares are computed on the 'Total budget % per objective' column, which allocates evaluation, PMC, contingency and fee proportionally to each objective's deliverable budget.

Sheet List of Deliverables
A1: List of Deliverables
A3: Outcome | B3: Deliverable Number | C3: Deliverable Title
A4: Outcome 1.1 | B4: D1 | C4: D1. Status report on capacity building of NDA and climate stakeholders
B5: D2 | C5: D2. Status report on country coordination mechanism, country (or regional) platform for enhanced climate finance access to develop, advance, and implement NDCs, NAPs and LTS
A6: Outcome 1.2 | B6: D3 | C6: D3. Status report on the national adaptation plan (NAP)
B7: D4 | C7: D4. Status report on the nationally determined contribution (NDC)
B8: D5 | C8: D5. Status report on the long term climate strategies (LTS)
B9: D6 | C9: D6. Status report on policies, regulations and mechanisms developed or enhanced to incentivize private sector engagement
A10: Outcome 1.3 | B10: D7 | C10: D7. Status report on capacity building of direct access applicants and accredited entities to meet GCF accreditation requirements
A11: Outcome 2.1 | B11: D8 | C11: D8. Country Programme Document
A12: Outcome 2.2 | B12: D9 | C12: D9. Concept Note(s), and studies, assessment, reports, etc. to support the development of investment-grade Concept Notes
B13: D10 | C13: D10. Funding Proposal(s), and studies, assessment, reports, etc. to support the development of investment-grade Funding Proposals
A14: Outcome 2.3 | B14: D11 | C14: D11. Status report on capacity building of NDA and DAEs in project/ program design, implementation and oversight
A15: Outcome 3.1 | B15: D12 | C15: D12. Knowledge Products / Compendium of Knowledge Products produced (Policies, Programme, NDC, NAP, LTS, L&D, TNA and others related)
B16: D13 | C16: D13. Status report on the knowledge sharing events and knowledge sharing platform promoted
A17: Outcome 3.2 | B17: D14 | C17: D14. Status report on the regional or South-South partnerships, programmes, policies, MOUs and/or collaboration mechanisms promoted
